## 9 异常

### 9.1 引入异常

> 运行下面的代码，看看有什么问题?
>
> public static void main(String[] args) {
> int num1 = 10;
> int num2 = 0;
> int res = num1 / num2;
> System.out.println("程序继续运行....");
> }

~~~java
public class Exception01 {
    public static void main(String[] args) {

        int num1 = 10;
        int num2 = 0;
        /*
            1.当程序执行时,程序就会出现异常 ArithmeticException(算术异常)
            2.当抛出异常后,程序就退出了,下面的代码就不在执行了
            3.如果程序员，认为一段代码可能出现异常/问题，可以使用 try-catch 异常处理机制来解决,从而保证程序的健壮性
            4.将该代码块->选中->快捷键 ctrl + alt + t -> 选中 try-catch
            5.如果进行异常处理，那么即使出现了异常，程序可以继续执行
         */
        try {
            int res = num1 / num2;
        } catch (Exception e) {
            //e.printStackTrace();
            System.out.println("打印异常信息: " + e.getMessage());//输出异常信息
        }
        System.out.println("程序是否继续运行");
    }
}
~~~

### 9.2 异常介绍

> 说明
>
> java语言中,将程序执行中发生的不正常情况称为"异常"
>
> 通常分为两类:
>
> 1.ERROR(错误):java虚拟机无法解决的严重问题,如JVM系统内部错误,资源耗尽等情况,StackOverFlowError/OOM,ERROR是严重错误程序会崩溃
>
> 2.Exception:其他因编程错误或偶然的外在因素导致的一致性问题,可以使用针对性的代码进行处理,例如空指针的访问,师徒读取不存在的文件,网络连接中断等等;Exception异常分为两大类:<font color='cyan'>运行时异常</font>[程序运行时,发生的异常]和<font color='cyan'>编译时异常</font>[编程时,编译器检查出的异常]

### 9.3 异常体系图一览(!!)

<img src="F:\Typora_note\java\04 韩顺平\hsp.assets\image-20220410171528992.png" alt="image-20220410171528992" style="zoom:50%;" />

> 说明:
>
> 1.异常分为两大类:运行时异常和编译时异常
>
> 2.运行时异常,编译器无法检测出来,一般是指编程时的逻辑错误,是程序员应该避免出现的异常,java.lang.RuntimeException类及它的子类都是运行时异常
>
> 3.对于运行时异常,可以不作处理,因为这类异常很普遍,若全部处理可能会对程序的可读性和运行效率产生影响
>
> 4.编译时运行,是编译器要求必须处理的异常

### 9.4 常见的运行时异常

> 1) NullPointerException 空指针异常
>
> 2) ArithmeticException 数学运算异常
> 3) ArrayIndexOutOfBoundsException 数组下标越界异常
> 4) ClassCastException 类型转换异常
> 5) NumberFormatException 数字格式不正确异常[]

~~~java
// 1.NullPointerException:当应用程序试图在需要对象的地方使用 null 时，抛出该异常
public class Exception01 {
    public static void main(String[] args) {

        String name = null;
        System.out.println(name.length());
    }
}
~~~

~~~java
//2.ArithmeticException:当出现异常的运算条件时，抛出此异常。例如，一个整数“除以零”时
//见"异常引入"章节
~~~

~~~java
//3.ArrayIndexOutOfBoundsException:用非法索引访问数组时抛出的异常。如果索引为负或大于等于数组大小，则该索引为非法索引
public class Exception02 {
    public static void main(String[] args) {
        int[] arr = {1,2,4};
        for (int i=0; i <= arr.length; i++){
            System.out.println(arr[i]);
        }
    }
}
~~~

~~~java
//4.ClassCastException:当试图将对象强制转换为不是实例的子类时，抛出该异常。
public class Exception03 {
    public static void main(String[] args) {
        A a = new B();
        B b = (B)a;//ok
        C c = (C)a;//将B --> C
    }
}

class A {}
class B extends A {}
class C extends A {}
~~~

~~~java
//5.NumberFormatException:当应用程序试图将字符串转换成一种数值类型，但该字符串不能转换为适当格式时，抛出该异常 => 使用异常我们可以确保输入是满足条件数字.
public class Exception04 {
    public static void main(String[] args) {
        String name = "1234";
        int num = Integer.parseInt(name);
        System.out.println(num);

        String name1 = "韩顺平";
        int num1 = Integer.parseInt(name1);
        System.out.println(num1);
    }
}
~~~

### 9.5 编译异常

> 说明
>
> 1.编译异常是指在编译期间,就必须处理的异常,否则代码不能通过编译
>
> 2.常见的编译异常
>
> SQLException 操作数据库时,查询表发现异常
>
> IOException 操作文件时,发生异常
>
> FileNotFoundException 当操作一个不存在的文件时,发生异常
>
> ClassNotFoundException 加载类,而类不存在的异常
>
> EOFException 操作文件到文件末尾发生异常
>
> illegalArgumentException 参数异常

### 9.6 异常练习题

<img src="F:\Typora_note\java\04 韩顺平\hsp.assets\image-20220410175032080.png" alt="image-20220410175032080" style="zoom:50%;" />

### 9.7 异常处理

> 说明
>
> 异常处理就是当异常发生时,对异常处理的方式
>
> java中提供2个处理方式:
>
> 1.try-catch-finally : 程序员在代码中捕获发生的异常,自行处理
>
> 2.throws : 将发生的异常抛出,交给调用者(方法来处理),最顶级的处理就是JVN

~~~java
// try-catch-finally机制
try {
    代码1;//存在异常
}catch(Exception e){
    /*
    1.捕获到异常
    2.当系统发生异常时,系统将异常封装成Exception对象e,传递给catch
    3.得到异常对象后,就可以自己处理
    4.注意:如果没有发生异常,catch块是不会执行的
    */
} finally {
    /*
     1.不管try代码块是否有异常发生,始终要执行finally
     2.通常将关闭(释放)资源代码放在finally里面
    */
}


~~~

~~~java
// throws处理机制
// JVM --> main --> f1() ---> f2()[发生异常]---通过throws-->f1()[此时有try-catch/throws]--通过throws-->main[此时有try-catch/throws] ---通过throws--->JVM
// 每个环节处理的异常也只能[try-catch/throws]取其一
//最顶级的JVM:输出异常信息/退出程序
//如果没有显示的使用try-catch/throws处理异常,默认使用throws Exception
~~~

<img src="F:\Typora_note\java\04 韩顺平\hsp.assets\image-20220410184810069.png" alt="image-20220410184810069" style="zoom:50%;" />

### 9.8 try-catch 异常处理

> 说明:
>
> java提供try-catch块来处理异常,try用于包含可能出错的代码,catch块用于处理try块中发生的异常,可以根据需求在程序中有多个try-catch块
>
> 1.基本语法
>
> try{
>
> //可疑代码
>
> //将异常生成的异常现象传递给catch块
>
> }catch{
>
> //对异常进行处理
>
> }
>
> //如果没有finally语法也是允许的
>
> 2.try-catch细节
>
> ① 如果异常发生了，则异常发生后面的代码不会执行，直接进入到 catch 块
>
> ② 如果异常没有发生，则顺序执行 try 的代码块，不会进入到 catch
>
> ③ 如果希望不管是否发生异常，都执行某段代码(比如关闭连接，释放资源等)则使用如下代码- finally
>
> ④ 可以有多个catch语句,捕获不同的异常,要求父类异常在后,子类异常在前,比如Exception在后,NullPointerException在前,如果发生异常,只会匹配一个catch
>
> ⑤ 可以直接使用try-finally配合使用,这种用法相当于没有捕获异常,因此程序会直接崩掉;应用场景:就是执行一段代码,不管是否发生异常,都必须执行某个业务逻辑

~~~java
public class Exception01 {
    public static void main(String[] args) {
        //try -catch
        //1. 如果异常发生了，则异常发生后面的代码不会执行，直接进入到 catch 块
        //2. 如果异常没有发生，则顺序执行 try 的代码块，不会进入到 catch
        //3. 如果希望不管是否发生异常，都执行某段代码(比如关闭连接，释放资源等)则使用如下代码- finally

        try {
            String name1 = "韩顺平";
            int num1 = Integer.parseInt(name1);//发生异常
            System.out.println("数字" + num1);//这处代码就不会执行
        } catch (NumberFormatException e) {
            System.out.println("异常信息" + e.getMessage());
        } finally {
            System.out.println("finally执行...");
        }
        System.out.println("程序继续运行");

        //4.可以有多个catch语句,捕获不同的异常,要求父类异常在后,子类异常在前,比如Exception在后,NullPointerException在前,如果发生异常,只会匹配一个catch
        /*
            如果try代码块有多个异常
            可以使用多个 catch 分别捕获不同的异常，相应处理
            要求子类异常写在前面，父类异常写在后面
         */
        try {
            Person person = new Person();
            person = null;
            System.out.println(person.getName()); //NullPointerException
            int n1 = 10;
            int n2 = 0;
            int res = n1 / n2; //ArithmeticException
        } catch (NullPointerException e) {
            System.out.println("空指针异常" + e.getMessage());
        } catch (ArithmeticException e) {
            System.out.println("算数异常" + e.getMessage());
        } catch (Exception e) {
            System.out.println(e.getMessage());
        }

        //5.可以直接使用try-finally配合使用,这种用法相当于没有捕获异常,因此程序会直接崩掉;应用场景:就是执行一段代码,不管是否发生异常,都必须执行某个业务逻辑
        /*
            try{
            //代码
            }finally{
            //总是执行
            }
         */
        try {
            int n3 =100;
            int n4 = 0;
            int result = n3 /n4;
        } finally {
            System.out.println("执行finally");
        }
        System.out.println("程序继续");
    }
}

class Person {

    private String name = "jack";

    public String getName() {
        return name;
    }

}
~~~

#### 9.8.1 异常练习题

 ~~~java
public class Exception02 {
    public static int method() {
        try {
            String[] names = new String[3];
            if (names[1].equals("222")) { // 空指针
                System.out.println(names[1]);
            } else {
                names[3] = "444";//数组越界
            }
            return 1;
        } catch (ArrayIndexOutOfBoundsException e) {
            return 2;
        } catch (NullPointerException e) {
            return 3;
        } finally {
            return 4;
        }

    }

    public static void main(String[] args) {
        System.out.println(method()); //4
    }
}
 ~~~

> try-catch-finally执行顺序小结
>
> 1) 如果没有出现异常,则执行try块中所有的语句,不执行catch块中的语句,如果有finally,最后还需要执行finally里面的语句
>
> 2) 如果出现异常,则try块中异常发生后,try块剩下的语句不再执行,将执行try块中的语句,如果有finally,最后还需要执行finally里面的语句

~~~java
// 如果用户输入的不是一个整数，就提示他反复输入，直到输入一个整数为止
public class Exception03 {
    public static void main(String[] args) {
        Scanner scanner = new Scanner(System.in);

      for (;;){
           System.out.println("输入: ");
           String n1 = scanner.next();
            try {
              int n2 = Integer.parseInt(n1);
               break;
           } catch (Exception e) {
               System.out.println(e.getMessage());
            }
        }
        // 自己写的碰到的原因:nextInt方法在发生异常后，不再接受用户输入的任何数据，而是徘徊在异常区域，如果外部使用死循环，就会导致死循环的发生。;解决方法：重新实例化Scanner对象 用new Scanner(System.in)代替上述代码中的sc即可
        // 当输入非整型数时，系统会抛出 InputMismatchException 异常时不会清除键盘缓冲区中的字符串，因此循环调用nextInt()时,仍然能够读取到上次输入的字符串,导致陷入死循环，
        // 使用新对象,会"清空"缓冲? 而使用next() + Integer.parseInt() 则不会产生此问题。
//        方法1:实例化Scanner对象 用new Scanner(System.in)代替代码中的scanner即可
        for (;;){
            System.out.println("输入: ");
            try {
//                scanner.nextInt();
                new Scanner(System.in).nextInt();
                break;
            } catch (Exception e) {
                System.out.println(e.getMessage());
            }
        }

        // 方法2:catch中，加一句：input.next()
        for (;;){
            System.out.println("输入: ");
            try {
                scanner.nextInt();
                new Scanner(System.in).nextInt();
                break;
            } catch (Exception e) {
                System.out.println(e.getMessage());
                scanner.nextInt();
            }
        }
    }
}
~~~

### 9.9 throws 异常处理

#### 9.9.1 throws异常基础

> 1.如果一个方法(的语句执行时)可能生成某种异常,但是并不能确定如何处理这种异常,则此方法应显示的声明抛出异常,表明该方法将不对这些异常进行处理,而是<font color='cyan'>由该方法的调用者负责处理</font>
>
> 2.在方法声明中用throws语句可以声明抛出异常的列表(多个异常),throws后面的异常类型可以是方法中产生的异常类型,也可以是它(异常)的父类

~~~java
import java.io.FileInputStream;
import java.io.FileNotFoundException;

/**
 * throws
 */
public class Throws01 {
    public static void main(String[] args) {

    }
    //throws后面的异常类型可以是方法中产生的异常类型,也可以是它(异常)的父类 FileNotFoundException/Exception
    //在方法声明中用throws语句可以声明抛出异常的列表(多个异常)
    public void f2() throws FileNotFoundException, NullPointerException, ArithmeticException{
        //创建一个文件流对象
        //此时编译就异常:未处理 异常: java.io.FileNotFoundException
        //处理方式: 1.try-catch;2.使用throws抛出异常(throws FileNotFoundException),让调用f1()的调用者(方法)处理
        FileInputStream fileInputStream = new FileInputStream("d://aaa.com");
    }
}
~~~

#### 9.9.2 throws异常细节

> 1.对于编译异常,程序中必须处理,比如try-catch或者throws
>
> 2.对于运行时异常,程序中如果没有处理,默认使用throws的方式处理
>
> 3.子类重写父类的方法时,对抛出异常的规定:子类重写的方法,所抛出的异常类型要么和子类的异常一致.要么为父类抛出异常类型的子类型
>
> 4.在throws过程中,如果有方法try-catch,就相当于处理异常,就可以不必throws

~~~java
import java.io.FileInputStream;
import java.io.FileNotFoundException;

/**
 *  ThrowsDetail
 */
public class ThrowsDetail01 {
    public static void main(String[] args) //throws ArithmeticException --默认
    {
        f1();
    }

    public static void f1() //throws ArithmeticException --默认
    {
        //1.对于编译异常,程序中必须处理,比如try-catch或者throws
        //2.对于运行时异常,程序中如果没有处理,默认使用throws的方式处理(默认的方式)
        int n1 = 10;
        int n2 = 0;
        double n3 = n1 / n2;
    }

    public static void f2() throws FileNotFoundException{
        //思考:此时调用f3()会怎么样?
        //发现会报错:未处理 异常: java.io.FileNotFoundException? 原因是什么呢?
        //1.因为f3()抛出的是一个编译异常FileNotFoundException
        //2.这时,就要去f2()必须处理这个编译异常
        f3();//抛出异常(要么1.try-catch;2.继续throws)
    }

    public static void f3() throws FileNotFoundException {
        FileInputStream fileInputStream = new FileInputStream("d://aaa.com");
    }

    public static void f4(){
        //此时这里调用f5会有报错吗?
        //1.发现没有错,因为f5()是拥有运行时异常,
        //2.而java中并不要求一定要处理运行异常,因为有默认处理机制
        f5();
    }

    public static void f5() throws ArithmeticException{

    }
}

//3.子类重写父类的方法时,对抛出异常的规定:子类重写的方法,所抛出的异常类型要么和子类的异常一致.要么为父类抛出异常类型的子类型
class Father{

    public void method() throws RuntimeException{

    }
}

class Son extends Father{
    @Override
    public void method() throws NullPointerException{
//        public void method() throws Exception{  //大于异常父类
//        public void method() throws FileNotFoundException { //非异常子类

    }
}
~~~

### 9.10 自定义异常

> 说明:
>
> 当程序中出现了某些"错误",但是该错误信息并没有在Throwable子类中描述处理,这个时候就可以自己设计异常类来描述该错误信息
>
> 步骤:
>
> 1)定义类:自定义异常类名(自己写)继承Exception或者RuntimeException
>
> 2)如果继承Exception,属于编译异常
>
> 3)如果继承RuntimeException,属于运行异常(一般来说,继承RuntimeException)
>
> 4)throw + 异常对象

~~~java
public class Exception01 {
    public static void main(String[] args) {
        //当我们接收Person对象年龄时,要求范围在18 -120之间,
        //否则抛出自定义异常(要求继承RuntimeException),并给出提示信息

        int age = 180;
        if (!(age >= 18 && age < 120)){
            throw new AgeException("年龄需要在10-120岁");
        }
        System.out.println("年龄范围正确");
    }
}

//自定义异常类
/*
    1.继承RuntimeException
    2.编写构造器
    3.一般来说,继承RuntimeException做成运行时异常:好处时,我们可以使用默认的处理机制
 */
class AgeException extends RuntimeException{
    public AgeException(String message) {
        super(message);
    }
}
~~~

### 9.11 throw 和 throws 的区别

|        | 意义                   | 位置       | 后面跟的东西 |
| ------ | ---------------------- | ---------- | ------------ |
| throws | 异常处理的一种方式     | 方法声明处 | 异常的类型   |
| throw  | 自定义异常对象的关键字 | 方法体中   | 异常的对象   |

~~~java
public class Exception02 {
    public static void main(String[] args) {
        try {
            ReturnExceptionDemo.methodA();
        } catch (Exception e) {
            System.out.println(e.getMessage()); //3 制造异常
        }
            ReturnExceptionDemo.methodB();//这里还是会继续运行
    }
}

class ReturnExceptionDemo{
    static void methodA(){
        try {
            System.out.println("进入A方法"); //1
            throw new RuntimeException("制造异常");
        }finally {
            System.out.println("A方法的finally"); //2
        }
    }

    static void methodB(){
        try {
            System.out.println("进入B方法");// 4
            return;
        } finally {
            System.out.println("B方法的finally");// 5
        }
    }
}
~~~

### 9.12 练习题

~~~java
/**
 * 1.编写应用程序EcmDef.java,接收命令行的两个参数(整数),计算两数相除
 * 2.计算两个数相除,要求使用方法cal(int n1, int n2)
 * 3.对数据格式不正确(NumberFormatException),缺少命令行参数(ArrayIndexOutOfBoundsException)/除0进行异常处理(ArithmeticException)
 */
public class Exception01 {
    public static void main(String[] args) {

        try {
            //先验证输入的参数的个数是否正确
            if (args.length != 2) {
                throw new ArrayIndexOutOfBoundsException("参数个数不对");
            }
            //先把接收到的参数,转成整数
            int n1 = Integer.parseInt(args[0]);
            int n2 = Integer.parseInt(args[1]);
            //计算方法
            double res = cal(n1, n2);
        } catch (ArrayIndexOutOfBoundsException e) {
            System.out.println(e.getMessage());
        } catch (NumberFormatException e) {
            System.out.println("参数格式不正确,需要输出整数");
        } catch (ArithmeticException e) {
            System.out.println("出现了分母为0的异常");
        }

    }

    public static double cal(int n1, int n2) {
        return n1 / n2;
    }
}
~~~

~~~java
/**
 *  说出一下代码是否会报错,是什么异常
 */
public class Exception02 {
    public static void main(String[] args) {
        if (args[4].equals("jhon")){ //可能发生 空指针/数组越界
            System.out.println("AA");
        }else {
            System.out.println("BB");
        }
        Object o = args[2]; //String -> Object ok
        Integer i = (Integer) o; // String -->int
    }
}
~~~

~~~java
/**
 * 写出结果: BCD
 */
public class Exception03 {
    public static void main(String[] args) {

        try {
            fun();
            System.out.println("A");
        } catch (Exception e) {
            System.out.println("C");
        }
        System.out.println("D");
    }

    public static void fun() {
        try {
            throw new RuntimeException();
        } finally {
            System.out.println("B");
        }
    }
}
~~~

~~~java
/**
 * 写出结果:BCD
 */
public class Exception04 {
    public static void main(String[] args) {
        try {
            showExec();
            System.out.println("A");
        } catch (Exception e) {
            System.out.println("B");
        } finally {
            System.out.println("C");
        }
        System.out.println("D");
    }

    public static void showExec() throws Exception {
        throw new Exception();
    }
}
~~~
